Workbook

Sheet Overview
A1: SANTA S1000D retrieval experiments: results summary
A2: Built from every results/**/*.json in the working tree on 2026-09-23 (plus superseded runs read from git HEAD 38dbabb). Metric: MRR. Only the S1000D_spec_sample target (21 test docs) is informative; the other targets have 2-6 test docs.
A4: Sheets
A5: All Runs | B5: One row per run: every JSON result file, with config, dev/test MRR, chance level and source path. Filterable.
A6: 12-pair Grids | B6: Pretrain source x finetune target test-MRR grids (T5, CodeT5, CodeT5 p1024, config A p1024/p2048) plus no-pretrain rows.
A7: S1000D Target | B7: All configs finetuned on S1000D_spec_sample (21 test docs): pooling fix, ablations, anonymized queries, no-pretrain controls.
A8: Same Domain | B8: Pretrain/finetune on the two halves of S1000D's own train split; pretraining gain on the harder vs. easier half.
A10: Experiment catalog
A11: Group | B11: Question | C11: Folders | D11: Status | E11: Key result
A12: 01_baselines | B12: Do T5 / CodeT5 / longer passages work out of the box? | C12: t5_s42, codet5_s42, cnt_p256_s42, cnt_p1024_s42 | D12: Valid | E12: Everything at chance. Cause: first-token decoder pooling collapses all embeddings (doc-doc cosine 1.000).
A13: 02_pooling_fix | B13: Does mean pooling (+ cosine) fix the collapse? Does pretraining help? | C13: fixA/B/C, nopre_meancos_s{42,1,2,3,4} | D13: Valid | E13: Mean+cosine: 0.90-0.93 on S1000D. No-pretrain control is as good or better: no pretraining benefit.
A14: 02_pooling_fix | B14: Config A on the small targets | C14: allA_meancos_p{1024,2048}_s42, nopreAll_meancos_s{42,1,2} | D14: Undocumented | E14: Not in results/README.md. 2-6 test docs per target: too noisy to conclude.
A15: 03_query_leakage | B15: Are the queries too easy because they quote identifiers? | C15: anonq_meancos_s{42,1,2}, anonq_nopre_s{42,1,2} | D15: Valid | E15: BM25 still 0.976 on anonymized queries. Dense drops to ~0.87. Still no pretraining benefit.
A16: 04_pool_size | B16: Is the 21-doc pool what makes BM25 unbeatable? | C16: pool332, pool332_{orig,anon}[_nopre]_s42 | D16: Valid | E16: Yes. On 332 docs BM25 falls to ~0.12, dense ~0.50-0.66: dense clearly wins. Still no pretraining benefit (1 seed).
A17: 05_pretrain_diagnosis | B17: Is MEP loss or too few pretrain steps the reason pretraining doesn't help? | C17: mepablate_s42, longpretrain100_s42 | D17: Valid | E17: Neither. MEP off and 10x epochs both leave test MRR roughly unchanged.
A18: 06_same_domain | B18: Does pretraining help when pretrain and finetune share content? | C18: samedomain_s{42,1,2}, samedomain_alt_s42 | D18: Valid | E18: Yes, on the harder half: +0.06 to +0.13 in every run. Easier half: ~0 to +0.04.
A20: Reference numbers (hardcoded, not in the JSON files)
A21: Quantity | B21: Value | C21: Source
A22: BM25, 21-doc pool, original queries | B22: 1 | C22: santa/diagnostics/bm25_baseline.py; results/README.md
A23: BM25, 21-doc pool, anonymized queries | B23: 0.9762 | C23: bm25_baseline.py on retrieval_anonq; results/README.md
A24: Chance MRR, 21 docs (S1000D test) | B24: 0.1736 | C24: H(21)/21
A25: Chance MRR, 6 docs (BIKE_7 test) | B25: 0.4083 | C25: H(6)/6
A26: Chance MRR, 3 docs (s1kd-tools-doc test) | B26: 0.6111 | C26: H(3)/3
A27: Chance MRR, 2 docs (FOSSIG test) | B27: 0.75 | C27: H(2)/2
A29: Legend
A30: Blue text | B30: Hardcoded value (reference numbers above, taken from results/README.md / diagnostics).
A31: Black text | B31: Values read from JSON (All Runs) or formulas pulling from All Runs.
A32: Green / red fill | B32: Test - chance > 0.05 (green); within +/-0.02 of chance (red, i.e. collapsed).
A33: Status fill | B33: Yellow = undocumented; red = questionable / superseded.

Sheet All Runs
A1: Key | B1: Group | C1: Experiment tag | D1: Status | E1: Seed | F1: Pretrain source | G1: Finetune target | H1: Model | I1: Pooling / scoring | J1: p_max_len | K1: Query set | L1: Candidate docs | M1: Pretrain dev MRR | N1: Finetune dev MRR | O1: Test MRR | P1: Chance MRR | Q1: Test - chance | R1: Notes | S1: Source file
A2: cnt_p1024_s42|BIKE_7_to_FOSSIG | B2: 01_baselines | C2: cnt_p1024_s42 | D2: Valid | E2: 42 | F2: BIKE_7 | G2: FOSSIG | H2: codet5-base | I2: first-token decoder state, dot | J2: 1024 | K2: original | L2: 2 | M2: 0.61111111 | N2: 0.75 | O2: 0.75 | P2: 0.75 | Q2: =IF(AND(ISNUMBER(O2),ISNUMBER(P2)),O2-P2,"") -> 0 | R2: Embedding collapse -> chance | S2: results/01_baselines/cnt_p1024_s42/BIKE_7_to_FOSSIG/eval_test.json
A3: cnt_p1024_s42|BIKE_7_to_S1000D_spec_sample | B3: 01_baselines | C3: cnt_p1024_s42 | D3: Valid | E3: 42 | F3: BIKE_7 | G3: S1000D_spec_sample | H3: codet5-base | I3: first-token decoder state, dot | J3: 1024 | K3: original | L3: 21 | M3: 0.61111111 | N3: 0.19887137 | O3: 0.15375841 | P3: 0.1736 | Q3: =IF(AND(ISNUMBER(O3),ISNUMBER(P3)),O3-P3,"") -> -0.019841594 | R3: Embedding collapse -> chance | S3: results/01_baselines/cnt_p1024_s42/BIKE_7_to_S1000D_spec_sample/eval_test.json
A4: cnt_p1024_s42|BIKE_7_to_s1kd-tools-doc | B4: 01_baselines | C4: cnt_p1024_s42 | D4: Valid | E4: 42 | F4: BIKE_7 | G4: s1kd-tools-doc | H4: codet5-base | I4: first-token decoder state, dot | J4: 1024 | K4: original | L4: 3 | M4: 0.61111111 | N4: 0.5625 | O4: 0.83333333 | P4: 0.6111 | Q4: =IF(AND(ISNUMBER(O4),ISNUMBER(P4)),O4-P4,"") -> 0.22223333 | R4: Embedding collapse -> chance | S4: results/01_baselines/cnt_p1024_s42/BIKE_7_to_s1kd-tools-doc/eval_test.json
A5: cnt_p1024_s42|FOSSIG_to_BIKE_7 | B5: 01_baselines | C5: cnt_p1024_s42 | D5: Valid | E5: 42 | F5: FOSSIG | G5: BIKE_7 | H5: codet5-base | I5: first-token decoder state, dot | J5: 1024 | K5: original | L5: 6 | M5: 0.75 | N5: 0.61111111 | O5: 0.40833333 | P5: 0.4083 | Q5: =IF(AND(ISNUMBER(O5),ISNUMBER(P5)),O5-P5,"") -> 3.3333333e-05 | R5: Embedding collapse -> chance | S5: results/01_baselines/cnt_p1024_s42/FOSSIG_to_BIKE_7/eval_test.json
A6: cnt_p1024_s42|FOSSIG_to_S1000D_spec_sample | B6: 01_baselines | C6: cnt_p1024_s42 | D6: Valid | E6: 42 | F6: FOSSIG | G6: S1000D_spec_sample | H6: codet5-base | I6: first-token decoder state, dot | J6: 1024 | K6: original | L6: 21 | M6: 0.75 | N6: 0.23389151 | O6: 0.19756524 | P6: 0.1736 | Q6: =IF(AND(ISNUMBER(O6),ISNUMBER(P6)),O6-P6,"") -> 0.023965238 | R6: Embedding collapse -> chance | S6: results/01_baselines/cnt_p1024_s42/FOSSIG_to_S1000D_spec_sample/eval_test.json
A7: cnt_p1024_s42|FOSSIG_to_s1kd-tools-doc | B7: 01_baselines | C7: cnt_p1024_s42 | D7: Valid | E7: 42 | F7: FOSSIG | G7: s1kd-tools-doc | H7: codet5-base | I7: first-token decoder state, dot | J7: 1024 | K7: original | L7: 3 | M7: 0.75 | N7: 0.52083333 | O7: 0.61111111 | P7: 0.6111 | Q7: =IF(AND(ISNUMBER(O7),ISNUMBER(P7)),O7-P7,"") -> 1.1111111e-05 | R7: Embedding collapse -> chance | S7: results/01_baselines/cnt_p1024_s42/FOSSIG_to_s1kd-tools-doc/eval_test.json
A8: cnt_p1024_s42|S1000D_spec_sample_to_BIKE_7 | B8: 01_baselines | C8: cnt_p1024_s42 | D8: Valid | E8: 42 | F8: S1000D_spec_sample | G8: BIKE_7 | H8: codet5-base | I8: first-token decoder state, dot | J8: 1024 | K8: original | L8: 6 | M8: 0.21941253 | N8: 0.61111111 | O8: 0.42222222 | P8: 0.4083 | Q8: =IF(AND(ISNUMBER(O8),ISNUMBER(P8)),O8-P8,"") -> 0.013922222 | R8: Embedding collapse -> chance | S8: results/01_baselines/cnt_p1024_s42/S1000D_spec_sample_to_BIKE_7/eval_test.json
A9: cnt_p1024_s42|S1000D_spec_sample_to_FOSSIG | B9: 01_baselines | C9: cnt_p1024_s42 | D9: Valid | E9: 42 | F9: S1000D_spec_sample | G9: FOSSIG | H9: codet5-base | I9: first-token decoder state, dot | J9: 1024 | K9: original | L9: 2 | M9: 0.21941253 | N9: 0.75 | O9: 0.75 | P9: 0.75 | Q9: =IF(AND(ISNUMBER(O9),ISNUMBER(P9)),O9-P9,"") -> 0 | R9: Embedding collapse -> chance | S9: results/01_baselines/cnt_p1024_s42/S1000D_spec_sample_to_FOSSIG/eval_test.json
A10: cnt_p1024_s42|S1000D_spec_sample_to_s1kd-tools-doc | B10: 01_baselines | C10: cnt_p1024_s42 | D10: Valid | E10: 42 | F10: S1000D_spec_sample | G10: s1kd-tools-doc | H10: codet5-base | I10: first-token decoder state, dot | J10: 1024 | K10: original | L10: 3 | M10: 0.21941253 | N10: 0.54166667 | O10: 0.61111111 | P10: 0.6111 | Q10: =IF(AND(ISNUMBER(O10),ISNUMBER(P10)),O10-P10,"") -> 1.1111111e-05 | R10: Embedding collapse -> chance | S10: results/01_baselines/cnt_p1024_s42/S1000D_spec_sample_to_s1kd-tools-doc/eval_test.json
A11: cnt_p1024_s42|s1kd-tools-doc_to_BIKE_7 | B11: 01_baselines | C11: cnt_p1024_s42 | D11: Valid | E11: 42 | F11: s1kd-tools-doc | G11: BIKE_7 | H11: codet5-base | I11: first-token decoder state, dot | J11: 1024 | K11: original | L11: 6 | M11: 0.52083333 | N11: 0.61111111 | O11: 0.45555556 | P11: 0.4083 | Q11: =IF(AND(ISNUMBER(O11),ISNUMBER(P11)),O11-P11,"") -> 0.047255556 | R11: Embedding collapse -> chance | S11: results/01_baselines/cnt_p1024_s42/s1kd-tools-doc_to_BIKE_7/eval_test.json
A12: cnt_p1024_s42|s1kd-tools-doc_to_FOSSIG | B12: 01_baselines | C12: cnt_p1024_s42 | D12: Valid | E12: 42 | F12: s1kd-tools-doc | G12: FOSSIG | H12: codet5-base | I12: first-token decoder state, dot | J12: 1024 | K12: original | L12: 2 | M12: 0.52083333 | N12: 0.75 | O12: 0.75 | P12: 0.75 | Q12: =IF(AND(ISNUMBER(O12),ISNUMBER(P12)),O12-P12,"") -> 0 | R12: Embedding collapse -> chance | S12: results/01_baselines/cnt_p1024_s42/s1kd-tools-doc_to_FOSSIG/eval_test.json
A13: cnt_p1024_s42|s1kd-tools-doc_to_S1000D_spec_sample | B13: 01_baselines | C13: cnt_p1024_s42 | D13: Valid | E13: 42 | F13: s1kd-tools-doc | G13: S1000D_spec_sample | H13: codet5-base | I13: first-token decoder state, dot | J13: 1024 | K13: original | L13: 21 | M13: 0.52083333 | N13: 0.26076483 | O13: 0.17556277 | P13: 0.1736 | Q13: =IF(AND(ISNUMBER(O13),ISNUMBER(P13)),O13-P13,"") -> 0.0019627677 | R13: Embedding collapse -> chance | S13: results/01_baselines/cnt_p1024_s42/s1kd-tools-doc_to_S1000D_spec_sample/eval_test.json
... A67: fixA_meancos_p1024_s42|s1kd-tools-doc_to_S1000D_spec_sample | B67: 02_pooling_fix | C67: fixA_meancos_p1024_s42 | D67: Valid | E67: 42 | F67: s1kd-tools-doc | G67: S1000D_spec_sample | H67: codet5-base | I67: mean pooling, cosine (tau 0.05) | J67: 1024 | K67: original | L67: 21 | M67: 0.70833333 | N67: 0.83571429 | O67: 0.95238095 | P67: 0.1736 | Q67: =IF(AND(ISNUMBER(O67),ISNUMBER(P67)),O67-P67,"") -> 0.77878095 | R67: Best config ('config A') | S67: results/02_pooling_fix/fixA_meancos_p1024_s42/s1kd-tools-doc_to_S1000D_spec_sample/eval_test.json
A68: fixB_meandot_p1024_s42|BIKE_7_to_S1000D_spec_sample | B68: 02_pooling_fix | C68: fixB_meandot_p1024_s42 | D68: Valid | E68: 42 | F68: BIKE_7 | G68: S1000D_spec_sample | H68: codet5-base | I68: mean pooling, dot | J68: 1024 | K68: original | L68: 21 | M68: 0.61111111 | N68: 0.69897959 | O68: 0.85600907 | P68: 0.1736 | Q68: =IF(AND(ISNUMBER(O68),ISNUMBER(P68)),O68-P68,"") -> 0.68240907 | S68: results/02_pooling_fix/fixB_meandot_p1024_s42/BIKE_7_to_S1000D_spec_sample/eval_test.json
A69: fixB_meandot_p1024_s42|FOSSIG_to_S1000D_spec_sample | B69: 02_pooling_fix | C69: fixB_meandot_p1024_s42 | D69: Valid | E69: 42 | F69: FOSSIG | G69: S1000D_spec_sample | H69: codet5-base | I69: mean pooling, dot | J69: 1024 | K69: original | L69: 21 | M69: 0.75 | N69: 0.82380952 | O69: 0.84761905 | P69: 0.1736 | Q69: =IF(AND(ISNUMBER(O69),ISNUMBER(P69)),O69-P69,"") -> 0.67401905 | S69: results/02_pooling_fix/fixB_meandot_p1024_s42/FOSSIG_to_S1000D_spec_sample/eval_test.json
A70: fixB_meandot_p1024_s42|s1kd-tools-doc_to_S1000D_spec_sample | B70: 02_pooling_fix | C70: fixB_meandot_p1024_s42 | D70: Valid | E70: 42 | F70: s1kd-tools-doc | G70: S1000D_spec_sample | H70: codet5-base | I70: mean pooling, dot | J70: 1024 | K70: original | L70: 21 | M70: 0.70833333 | N70: 0.77380952 | O70: 0.92063492 | P70: 0.1736 | Q70: =IF(AND(ISNUMBER(O70),ISNUMBER(P70)),O70-P70,"") -> 0.74703492 | S70: results/02_pooling_fix/fixB_meandot_p1024_s42/s1kd-tools-doc_to_S1000D_spec_sample/eval_test.json
A71: fixC_meancos_p256_s42|BIKE_7_to_S1000D_spec_sample | B71: 02_pooling_fix | C71: fixC_meancos_p256_s42 | D71: Valid | E71: 42 | F71: BIKE_7 | G71: S1000D_spec_sample | H71: codet5-base | I71: mean pooling, cosine (tau 0.05) | J71: 256 | K71: original | L71: 21 | M71: 1 | N71: 0.71904762 | O71: 0.53849206 | P71: 0.1736 | Q71: =IF(AND(ISNUMBER(O71),ISNUMBER(P71)),O71-P71,"") -> 0.36489206 | S71: results/02_pooling_fix/fixC_meancos_p256_s42/BIKE_7_to_S1000D_spec_sample/eval_test.json
A72: fixC_meancos_p256_s42|FOSSIG_to_S1000D_spec_sample | B72: 02_pooling_fix | C72: fixC_meancos_p256_s42 | D72: Valid | E72: 42 | F72: FOSSIG | G72: S1000D_spec_sample | H72: codet5-base | I72: mean pooling, cosine (tau 0.05) | J72: 256 | K72: original | L72: 21 | M72: 0.75 | N72: 0.6792517 | O72: 0.59232804 | P72: 0.1736 | Q72: =IF(AND(ISNUMBER(O72),ISNUMBER(P72)),O72-P72,"") -> 0.41872804 | S72: results/02_pooling_fix/fixC_meancos_p256_s42/FOSSIG_to_S1000D_spec_sample/eval_test.json
A73: fixC_meancos_p256_s42|s1kd-tools-doc_to_S1000D_spec_sample | B73: 02_pooling_fix | C73: fixC_meancos_p256_s42 | D73: Valid | E73: 42 | F73: s1kd-tools-doc | G73: S1000D_spec_sample | H73: codet5-base | I73: mean pooling, cosine (tau 0.05) | J73: 256 | K73: original | L73: 21 | M73: 0.58333333 | N73: 0.58758503 | O73: 0.54814815 | P73: 0.1736 | Q73: =IF(AND(ISNUMBER(O73),ISNUMBER(P73)),O73-P73,"") -> 0.37454815 | S73: results/02_pooling_fix/fixC_meancos_p256_s42/s1kd-tools-doc_to_S1000D_spec_sample/eval_test.json
A74: nopreAll_meancos_p1024_s1|BIKE_7 | B74: 02_pooling_fix | C74: nopreAll_meancos_p1024_s1 | D74: Undocumented | E74: 1 | F74: (none) | G74: BIKE_7 | H74: codet5-base | I74: mean pooling, cosine (tau 0.05) | J74: 1024 | K74: original | L74: 6 | N74: 0.61111111 | O74: 0.63055556 | P74: 0.4083 | Q74: =IF(AND(ISNUMBER(O74),ISNUMBER(P74)),O74-P74,"") -> 0.22225556 | R74: No pretraining; small targets, too noisy to conclude | S74: results/02_pooling_fix/nopreAll_meancos_p1024_s1/BIKE_7/eval_test.json
A75: nopreAll_meancos_p1024_s1|FOSSIG | B75: 02_pooling_fix | C75: nopreAll_meancos_p1024_s1 | D75: Undocumented | E75: 1 | F75: (none) | G75: FOSSIG | H75: codet5-base | I75: mean pooling, cosine (tau 0.05) | J75: 1024 | K75: original | L75: 2 | N75: 0.75 | O75: 1 | P75: 0.75 | Q75: =IF(AND(ISNUMBER(O75),ISNUMBER(P75)),O75-P75,"") -> 0.25 | R75: No pretraining; small targets, too noisy to conclude | S75: results/02_pooling_fix/nopreAll_meancos_p1024_s1/FOSSIG/eval_test.json
A76: nopreAll_meancos_p1024_s1|s1kd-tools-doc | B76: 02_pooling_fix | C76: nopreAll_meancos_p1024_s1 | D76: Undocumented | E76: 1 | F76: (none) | G76: s1kd-tools-doc | H76: codet5-base | I76: mean pooling, cosine (tau 0.05) | J76: 1024 | K76: original | L76: 3 | N76: 0.6875 | O76: 0.66666667 | P76: 0.6111 | Q76: =IF(AND(ISNUMBER(O76),ISNUMBER(P76)),O76-P76,"") -> 0.055566667 | R76: No pretraining; small targets, too noisy to conclude | S76: results/02_pooling_fix/nopreAll_meancos_p1024_s1/s1kd-tools-doc/eval_test.json
A77: nopreAll_meancos_p1024_s2|BIKE_7 | B77: 02_pooling_fix | C77: nopreAll_meancos_p1024_s2 | D77: Undocumented | E77: 2 | F77: (none) | G77: BIKE_7 | H77: codet5-base | I77: mean pooling, cosine (tau 0.05) | J77: 1024 | K77: original | L77: 6 | N77: 0.61111111 | O77: 0.53333333 | P77: 0.4083 | Q77: =IF(AND(ISNUMBER(O77),ISNUMBER(P77)),O77-P77,"") -> 0.12503333 | R77: No pretraining; small targets, too noisy to conclude | S77: results/02_pooling_fix/nopreAll_meancos_p1024_s2/BIKE_7/eval_test.json
A78: nopreAll_meancos_p1024_s2|FOSSIG | B78: 02_pooling_fix | C78: nopreAll_meancos_p1024_s2 | D78: Undocumented | E78: 2 | F78: (none) | G78: FOSSIG | H78: codet5-base | I78: mean pooling, cosine (tau 0.05) | J78: 1024 | K78: original | L78: 2 | N78: 0.75 | O78: 1 | P78: 0.75 | Q78: =IF(AND(ISNUMBER(O78),ISNUMBER(P78)),O78-P78,"") -> 0.25 | R78: No pretraining; small targets, too noisy to conclude | S78: results/02_pooling_fix/nopreAll_meancos_p1024_s2/FOSSIG/eval_test.json
A79: nopreAll_meancos_p1024_s2|s1kd-tools-doc | B79: 02_pooling_fix | C79: nopreAll_meancos_p1024_s2 | D79: Undocumented | E79: 2 | F79: (none) | G79: s1kd-tools-doc | H79: codet5-base | I79: mean pooling, cosine (tau 0.05) | J79: 1024 | K79: original | L79: 3 | N79: 0.6875 | O79: 0.83333333 | P79: 0.6111 | Q79: =IF(AND(ISNUMBER(O79),ISNUMBER(P79)),O79-P79,"") -> 0.22223333 | R79: No pretraining; small targets, too noisy to conclude | S79: results/02_pooling_fix/nopreAll_meancos_p1024_s2/s1kd-tools-doc/eval_test.json
A80: nopreAll_meancos_p1024_s42|BIKE_7 | B80: 02_pooling_fix | C80: nopreAll_meancos_p1024_s42 | D80: Undocumented | E80: 42 | F80: (none) | G80: BIKE_7 | H80: codet5-base | I80: mean pooling, cosine (tau 0.05) | J80: 1024 | K80: original | L80: 6 | N80: 0.61111111 | O80: 0.53333333 | P80: 0.4083 | Q80: =IF(AND(ISNUMBER(O80),ISNUMBER(P80)),O80-P80,"") -> 0.12503333 | R80: No pretraining; small targets, too noisy to conclude | S80: results/02_pooling_fix/nopreAll_meancos_p1024_s42/BIKE_7/eval_test.json
A81: nopreAll_meancos_p1024_s42|FOSSIG | B81: 02_pooling_fix | C81: nopreAll_meancos_p1024_s42 | D81: Undocumented | E81: 42 | F81: (none) | G81: FOSSIG | H81: codet5-base | I81: mean pooling, cosine (tau 0.05) | J81: 1024 | K81: original | L81: 2 | N81: 0.75 | O81: 0.75 | P81: 0.75 | Q81: =IF(AND(ISNUMBER(O81),ISNUMBER(P81)),O81-P81,"") -> 0 | R81: No pretraining; small targets, too noisy to conclude | S81: results/02_pooling_fix/nopreAll_meancos_p1024_s42/FOSSIG/eval_test.json
A82: nopreAll_meancos_p1024_s42|s1kd-tools-doc | B82: 02_pooling_fix | C82: nopreAll_meancos_p1024_s42 | D82: Undocumented | E82: 42 | F82: (none) | G82: s1kd-tools-doc | H82: codet5-base | I82: mean pooling, cosine (tau 0.05) | J82: 1024 | K82: original | L82: 3 | N82: 0.6875 | O82: 0.83333333 | P82: 0.6111 | Q82: =IF(AND(ISNUMBER(O82),ISNUMBER(P82)),O82-P82,"") -> 0.22223333 | R82: No pretraining; small targets, too noisy to conclude | S82: results/02_pooling_fix/nopreAll_meancos_p1024_s42/s1kd-tools-doc/eval_test.json
A83: nopre_meancos_p1024_s1|S1000D_spec_sample | B83: 02_pooling_fix | C83: nopre_meancos_p1024_s1 | D83: Valid | E83: 1 | F83: (none) | G83: S1000D_spec_sample | H83: codet5-base | I83: mean pooling, cosine (tau 0.05) | J83: 1024 | K83: original | L83: 21 | N83: 0.94642857 | O83: 0.97619048 | P83: 0.1736 | Q83: =IF(AND(ISNUMBER(O83),ISNUMBER(P83)),O83-P83,"") -> 0.80259048 | R83: No-pretraining control | S83: results/02_pooling_fix/nopre_meancos_p1024_s1/S1000D_spec_sample/eval_test.json
A84: nopre_meancos_p1024_s2|S1000D_spec_sample | B84: 02_pooling_fix | C84: nopre_meancos_p1024_s2 | D84: Valid | E84: 2 | F84: (none) | G84: S1000D_spec_sample | H84: codet5-base | I84: mean pooling, cosine (tau 0.05) | J84: 1024 | K84: original | L84: 21 | N84: 0.91071429 | O84: 0.97619048 | P84: 0.1736 | Q84: =IF(AND(ISNUMBER(O84),ISNUMBER(P84)),O84-P84,"") -> 0.80259048 | R84: No-pretraining control | S84: results/02_pooling_fix/nopre_meancos_p1024_s2/S1000D_spec_sample/eval_test.json
A85: nopre_meancos_p1024_s3|S1000D_spec_sample | B85: 02_pooling_fix | C85: nopre_meancos_p1024_s3 | D85: Valid | E85: 3 | F85: (none) | G85: S1000D_spec_sample | H85: codet5-base | I85: mean pooling, cosine (tau 0.05) | J85: 1024 | K85: original | L85: 21 | N85: 0.87142857 | O85: 0.88095238 | P85: 0.1736 | Q85: =IF(AND(ISNUMBER(O85),ISNUMBER(P85)),O85-P85,"") -> 0.70735238 | R85: No-pretraining control | S85: results/02_pooling_fix/nopre_meancos_p1024_s3/S1000D_spec_sample/eval_test.json
... A87: nopre_meancos_p1024_s42|S1000D_spec_sample | B87: 02_pooling_fix | C87: nopre_meancos_p1024_s42 | D87: Valid | E87: 42 | F87: (none) | G87: S1000D_spec_sample | H87: codet5-base | I87: mean pooling, cosine (tau 0.05) | J87: 1024 | K87: original | L87: 21 | N87: 0.91071429 | O87: 0.91666667 | P87: 0.1736 | Q87: =IF(AND(ISNUMBER(O87),ISNUMBER(P87)),O87-P87,"") -> 0.74306667 | R87: No-pretraining control | S87: results/02_pooling_fix/nopre_meancos_p1024_s42/S1000D_spec_sample/eval_test.json
A88: anonq_meancos_p1024_s1|BIKE_7_to_S1000D_spec_sample | B88: 03_query_leakage | C88: anonq_meancos_p1024_s1 | D88: Valid | E88: 1 | F88: BIKE_7 | G88: S1000D_spec_sample | H88: codet5-base | I88: mean pooling, cosine (tau 0.05) | J88: 1024 | K88: anonymized | L88: 21 | M88: 0.61111111 | N88: 0.92857143 | O88: 0.89285714 | P88: 0.1736 | Q88: =IF(AND(ISNUMBER(O88),ISNUMBER(P88)),O88-P88,"") -> 0.71925714 | S88: results/03_query_leakage/anonq_meancos_p1024_s1/BIKE_7_to_S1000D_spec_sample/eval_test.json
A89: anonq_meancos_p1024_s1|FOSSIG_to_S1000D_spec_sample | B89: 03_query_leakage | C89: anonq_meancos_p1024_s1 | D89: Valid | E89: 1 | F89: FOSSIG | G89: S1000D_spec_sample | H89: codet5-base | I89: mean pooling, cosine (tau 0.05) | J89: 1024 | K89: anonymized | L89: 21 | M89: 0.75 | N89: 0.96428571 | O89: 0.82539683 | P89: 0.1736 | Q89: =IF(AND(ISNUMBER(O89),ISNUMBER(P89)),O89-P89,"") -> 0.65179683 | S89: results/03_query_leakage/anonq_meancos_p1024_s1/FOSSIG_to_S1000D_spec_sample/eval_test.json
A90: anonq_meancos_p1024_s1|s1kd-tools-doc_to_S1000D_spec_sample | B90: 03_query_leakage | C90: anonq_meancos_p1024_s1 | D90: Valid | E90: 1 | F90: s1kd-tools-doc | G90: S1000D_spec_sample | H90: codet5-base | I90: mean pooling, cosine (tau 0.05) | J90: 1024 | K90: anonymized | L90: 21 | M90: 0.875 | N90: 0.875 | O90: 0.84920635 | P90: 0.1736 | Q90: =IF(AND(ISNUMBER(O90),ISNUMBER(P90)),O90-P90,"") -> 0.67560635 | S90: results/03_query_leakage/anonq_meancos_p1024_s1/s1kd-tools-doc_to_S1000D_spec_sample/eval_test.json
A91: anonq_meancos_p1024_s2|BIKE_7_to_S1000D_spec_sample | B91: 03_query_leakage | C91: anonq_meancos_p1024_s2 | D91: Valid | E91: 2 | F91: BIKE_7 | G91: S1000D_spec_sample | H91: codet5-base | I91: mean pooling, cosine (tau 0.05) | J91: 1024 | K91: anonymized | L91: 21 | M91: 0.55555556 | N91: 0.9047619 | O91: 0.90238095 | P91: 0.1736 | Q91: =IF(AND(ISNUMBER(O91),ISNUMBER(P91)),O91-P91,"") -> 0.72878095 | S91: results/03_query_leakage/anonq_meancos_p1024_s2/BIKE_7_to_S1000D_spec_sample/eval_test.json
A92: anonq_meancos_p1024_s2|FOSSIG_to_S1000D_spec_sample | B92: 03_query_leakage | C92: anonq_meancos_p1024_s2 | D92: Valid | E92: 2 | F92: FOSSIG | G92: S1000D_spec_sample | H92: codet5-base | I92: mean pooling, cosine (tau 0.05) | J92: 1024 | K92: anonymized | L92: 21 | M92: 0.5 | N92: 0.875 | O92: 0.83333333 | P92: 0.1736 | Q92: =IF(AND(ISNUMBER(O92),ISNUMBER(P92)),O92-P92,"") -> 0.65973333 | S92: results/03_query_leakage/anonq_meancos_p1024_s2/FOSSIG_to_S1000D_spec_sample/eval_test.json
A93: anonq_meancos_p1024_s2|s1kd-tools-doc_to_S1000D_spec_sample | B93: 03_query_leakage | C93: anonq_meancos_p1024_s2 | D93: Valid | E93: 2 | F93: s1kd-tools-doc | G93: S1000D_spec_sample | H93: codet5-base | I93: mean pooling, cosine (tau 0.05) | J93: 1024 | K93: anonymized | L93: 21 | M93: 0.75 | N93: 0.87142857 | O93: 0.8015873 | P93: 0.1736 | Q93: =IF(AND(ISNUMBER(O93),ISNUMBER(P93)),O93-P93,"") -> 0.6279873 | S93: results/03_query_leakage/anonq_meancos_p1024_s2/s1kd-tools-doc_to_S1000D_spec_sample/eval_test.json
A94: anonq_meancos_p1024_s42|BIKE_7_to_S1000D_spec_sample | B94: 03_query_leakage | C94: anonq_meancos_p1024_s42 | D94: Valid | E94: 42 | F94: BIKE_7 | G94: S1000D_spec_sample | H94: codet5-base | I94: mean pooling, cosine (tau 0.05) | J94: 1024 | K94: anonymized | L94: 21 | M94: 0.55555556 | N94: 0.88095238 | O94: 0.8968254 | P94: 0.1736 | Q94: =IF(AND(ISNUMBER(O94),ISNUMBER(P94)),O94-P94,"") -> 0.7232254 | S94: results/03_query_leakage/anonq_meancos_p1024_s42/BIKE_7_to_S1000D_spec_sample/eval_test.json
...

Sheet 12-pair Grids
A1: Test MRR, pretrain source (rows) x finetune target (columns). Seed 42.
A3: T5, first-token pooling, dot, p256 (t5_s42)
A4: Pretrain \ Finetune | B4: bike | C4: s1kd-tools-doc | D4: fossig | E4: s1000d-spec | F4: Row mean
A5: bike | B5: — | C5: =IFERROR(INDEX('All Runs'!$O$2:$O$177,MATCH("t5_s42|BIKE_7_to_s1kd-tools-doc",'All Runs'!$A$2:$A$177,0)),"n/a") -> 0.61111111 | D5: =IFERROR(INDEX('All Runs'!$O$2:$O$177,MATCH("t5_s42|BIKE_7_to_FOSSIG",'All Runs'!$A$2:$A$177,0)),"n/a") -> 0.75 | E5: =IFERROR(INDEX('All Runs'!$O$2:$O$177,MATCH("t5_s42|BIKE_7_to_S1000D_spec_sample",'All Runs'!$A$2:$A$177,0)),"n/a") -> 0.16706291 | F5: =IFERROR(AVERAGE(B5:E5),"n/a") -> 0.50939134
A6: s1kd-tools-doc | B6: =IFERROR(INDEX('All Runs'!$O$2:$O$177,MATCH("t5_s42|s1kd-tools-doc_to_BIKE_7",'All Runs'!$A$2:$A$177,0)),"n/a") -> 0.49166667 | C6: — | D6: =IFERROR(INDEX('All Runs'!$O$2:$O$177,MATCH("t5_s42|s1kd-tools-doc_to_FOSSIG",'All Runs'!$A$2:$A$177,0)),"n/a") -> 0.75 | E6: =IFERROR(INDEX('All Runs'!$O$2:$O$177,MATCH("t5_s42|s1kd-tools-doc_to_S1000D_spec_sample",'All Runs'!$A$2:$A$177,0)),"n/a") -> 0.16657793 | F6: =IFERROR(AVERAGE(B6:E6),"n/a") -> 0.46941486
A7: fossig | B7: =IFERROR(INDEX('All Runs'!$O$2:$O$177,MATCH("t5_s42|FOSSIG_to_BIKE_7",'All Runs'!$A$2:$A$177,0)),"n/a") -> 0.43611111 | C7: =IFERROR(INDEX('All Runs'!$O$2:$O$177,MATCH("t5_s42|FOSSIG_to_s1kd-tools-doc",'All Runs'!$A$2:$A$177,0)),"n/a") -> 0.61111111 | D7: — | E7: =IFERROR(INDEX('All Runs'!$O$2:$O$177,MATCH("t5_s42|FOSSIG_to_S1000D_spec_sample",'All Runs'!$A$2:$A$177,0)),"n/a") -> 0.20247593 | F7: =IFERROR(AVERAGE(B7:E7),"n/a") -> 0.41656605
A8: s1000d-spec | B8: =IFERROR(INDEX('All Runs'!$O$2:$O$177,MATCH("t5_s42|S1000D_spec_sample_to_BIKE_7",'All Runs'!$A$2:$A$177,0)),"n/a") -> 0.43055556 | C8: =IFERROR(INDEX('All Runs'!$O$2:$O$177,MATCH("t5_s42|S1000D_spec_sample_to_s1kd-tools-doc",'All Runs'!$A$2:$A$177,0)),"n/a") -> 0.61111111 | D8: =IFERROR(INDEX('All Runs'!$O$2:$O$177,MATCH("t5_s42|S1000D_spec_sample_to_FOSSIG",'All Runs'!$A$2:$A$177,0)),"n/a") -> 0.75 | E8: — | F8: =IFERROR(AVERAGE(B8:E8),"n/a") -> 0.59722222
A9: Chance | B9: 0.4083 | C9: 0.6111 | D9: 0.75 | E9: 0.1736
A10: Test docs | B10: 6 | C10: 3 | D10: 2 | E10: 21
A12: CodeT5, first-token pooling, dot, p256 (codet5_s42)
A13: Pretrain \ Finetune | B13: bike | C13: s1kd-tools-doc | D13: fossig | E13: s1000d-spec | F13: Row mean
A14: bike | B14: — | C14: =IFERROR(INDEX('All Runs'!$O$2:$O$177,MATCH("codet5_s42|BIKE_7_to_s1kd-tools-doc",'All Runs'!$A$2:$A$177,0)),"n/a") -> 0.61111111 | D14: =IFERROR(INDEX('All Runs'!$O$2:$O$177,MATCH("codet5_s42|BIKE_7_to_FOSSIG",'All Runs'!$A$2:$A$177,0)),"n/a") -> 0.75 | E14: =IFERROR(INDEX('All Runs'!$O$2:$O$177,MATCH("codet5_s42|BIKE_7_to_S1000D_spec_sample",'All Runs'!$A$2:$A$177,0)),"n/a") -> 0.17765125 | F14: =IFERROR(AVERAGE(B14:E14),"n/a") -> 0.51292079
A15: s1kd-tools-doc | B15: =IFERROR(INDEX('All Runs'!$O$2:$O$177,MATCH("codet5_s42|s1kd-tools-doc_to_BIKE_7",'All Runs'!$A$2:$A$177,0)),"n/a") -> 0.40833333 | C15: — | D15: =IFERROR(INDEX('All Runs'!$O$2:$O$177,MATCH("codet5_s42|s1kd-tools-doc_to_FOSSIG",'All Runs'!$A$2:$A$177,0)),"n/a") -> 0.75 | E15: =IFERROR(INDEX('All Runs'!$O$2:$O$177,MATCH("codet5_s42|s1kd-tools-doc_to_S1000D_spec_sample",'All Runs'!$A$2:$A$177,0)),"n/a") -> 0.16955163 | F15: =IFERROR(AVERAGE(B15:E15),"n/a") -> 0.44262832
A16: fossig | B16: =IFERROR(INDEX('All Runs'!$O$2:$O$177,MATCH("codet5_s42|FOSSIG_to_BIKE_7",'All Runs'!$A$2:$A$177,0)),"n/a") -> 0.40833333 | C16: =IFERROR(INDEX('All Runs'!$O$2:$O$177,MATCH("codet5_s42|FOSSIG_to_s1kd-tools-doc",'All Runs'!$A$2:$A$177,0)),"n/a") -> 0.61111111 | D16: — | E16: =IFERROR(INDEX('All Runs'!$O$2:$O$177,MATCH("codet5_s42|FOSSIG_to_S1000D_spec_sample",'All Runs'!$A$2:$A$177,0)),"n/a") -> 0.16310217 | F16: =IFERROR(AVERAGE(B16:E16),"n/a") -> 0.39418221
A17: s1000d-spec | B17: =IFERROR(INDEX('All Runs'!$O$2:$O$177,MATCH("codet5_s42|S1000D_spec_sample_to_BIKE_7",'All Runs'!$A$2:$A$177,0)),"n/a") -> 0.43055556 | C17: =IFERROR(INDEX('All Runs'!$O$2:$O$177,MATCH("codet5_s42|S1000D_spec_sample_to_s1kd-tools-doc",'All Runs'!$A$2:$A$177,0)),"n/a") -> 0.61111111 | D17: =IFERROR(INDEX('All Runs'!$O$2:$O$177,MATCH("codet5_s42|S1000D_spec_sample_to_FOSSIG",'All Runs'!$A$2:$A$177,0)),"n/a") -> 0.75 | E17: — | F17: =IFERROR(AVERAGE(B17:E17),"n/a") -> 0.59722222
A18: Chance | B18: 0.4083 | C18: 0.6111 | D18: 0.75 | E18: 0.1736
A19: Test docs | B19: 6 | C19: 3 | D19: 2 | E19: 21
A21: CodeT5, first-token pooling, dot, p1024 (cnt_p1024_s42)
A22: Pretrain \ Finetune | B22: bike | C22: s1kd-tools-doc | D22: fossig | E22: s1000d-spec | F22: Row mean
A23: bike | B23: — | C23: =IFERROR(INDEX('All Runs'!$O$2:$O$177,MATCH("cnt_p1024_s42|BIKE_7_to_s1kd-tools-doc",'All Runs'!$A$2:$A$177,0)),"n/a") -> 0.83333333 | D23: =IFERROR(INDEX('All Runs'!$O$2:$O$177,MATCH("cnt_p1024_s42|BIKE_7_to_FOSSIG",'All Runs'!$A$2:$A$177,0)),"n/a") -> 0.75 | E23: =IFERROR(INDEX('All Runs'!$O$2:$O$177,MATCH("cnt_p1024_s42|BIKE_7_to_S1000D_spec_sample",'All Runs'!$A$2:$A$177,0)),"n/a") -> 0.15375841 | F23: =IFERROR(AVERAGE(B23:E23),"n/a") -> 0.57903058
A24: s1kd-tools-doc | B24: =IFERROR(INDEX('All Runs'!$O$2:$O$177,MATCH("cnt_p1024_s42|s1kd-tools-doc_to_BIKE_7",'All Runs'!$A$2:$A$177,0)),"n/a") -> 0.45555556 | C24: — | D24: =IFERROR(INDEX('All Runs'!$O$2:$O$177,MATCH("cnt_p1024_s42|s1kd-tools-doc_to_FOSSIG",'All Runs'!$A$2:$A$177,0)),"n/a") -> 0.75 | E24: =IFERROR(INDEX('All Runs'!$O$2:$O$177,MATCH("cnt_p1024_s42|s1kd-tools-doc_to_S1000D_spec_sample",'All Runs'!$A$2:$A$177,0)),"n/a") -> 0.17556277 | F24: =IFERROR(AVERAGE(B24:E24),"n/a") -> 0.46037277
A25: fossig | B25: =IFERROR(INDEX('All Runs'!$O$2:$O$177,MATCH("cnt_p1024_s42|FOSSIG_to_BIKE_7",'All Runs'!$A$2:$A$177,0)),"n/a") -> 0.40833333 | C25: =IFERROR(INDEX('All Runs'!$O$2:$O$177,MATCH("cnt_p1024_s42|FOSSIG_to_s1kd-tools-doc",'All Runs'!$A$2:$A$177,0)),"n/a") -> 0.61111111 | D25: — | E25: =IFERROR(INDEX('All Runs'!$O$2:$O$177,MATCH("cnt_p1024_s42|FOSSIG_to_S1000D_spec_sample",'All Runs'!$A$2:$A$177,0)),"n/a") -> 0.19756524 | F25: =IFERROR(AVERAGE(B25:E25),"n/a") -> 0.40566989
A26: s1000d-spec | B26: =IFERROR(INDEX('All Runs'!$O$2:$O$177,MATCH("cnt_p1024_s42|S1000D_spec_sample_to_BIKE_7",'All Runs'!$A$2:$A$177,0)),"n/a") -> 0.42222222 | C26: =IFERROR(INDEX('All Runs'!$O$2:$O$177,MATCH("cnt_p1024_s42|S1000D_spec_sample_to_s1kd-tools-doc",'All Runs'!$A$2:$A$177,0)),"n/a") -> 0.61111111 | D26: =IFERROR(INDEX('All Runs'!$O$2:$O$177,MATCH("cnt_p1024_s42|S1000D_spec_sample_to_FOSSIG",'All Runs'!$A$2:$A$177,0)),"n/a") -> 0.75 | E26: — | F26: =IFERROR(AVERAGE(B26:E26),"n/a") -> 0.59444444
A27: Chance | B27: 0.4083 | C27: 0.6111 | D27: 0.75 | E27: 0.1736
A28: Test docs | B28: 6 | C28: 3 | D28: 2 | E28: 21
A30: CodeT5, config A, p1024 (allA_meancos_p1024_s42; S1000D column from fixA_meancos_p1024_s42)
A31: Pretrain \ Finetune | B31: bike | C31: s1kd-tools-doc | D31: fossig | E31: s1000d-spec | F31: Row mean
A32: bike | B32: — | C32: =IFERROR(INDEX('All Runs'!$O$2:$O$177,MATCH("allA_meancos_p1024_s42|BIKE_7_to_s1kd-tools-doc",'All Runs'!$A$2:$A$177,0)),"n/a") -> 0.83333333 | D32: =IFERROR(INDEX('All Runs'!$O$2:$O$177,MATCH("allA_meancos_p1024_s42|BIKE_7_to_FOSSIG",'All Runs'!$A$2:$A$177,0)),"n/a") -> 0.75 | E32: =IFERROR(INDEX('All Runs'!$O$2:$O$177,MATCH("fixA_meancos_p1024_s42|BIKE_7_to_S1000D_spec_sample",'All Runs'!$A$2:$A$177,0)),"n/a") -> 0.8984127 | F32: =IFERROR(AVERAGE(B32:E32),"n/a") -> 0.82724868
A33: s1kd-tools-doc | B33: =IFERROR(INDEX('All Runs'!$O$2:$O$177,MATCH("allA_meancos_p1024_s42|s1kd-tools-doc_to_BIKE_7",'All Runs'!$A$2:$A$177,0)),"n/a") -> 0.65833333 | C33: — | D33: =IFERROR(INDEX('All Runs'!$O$2:$O$177,MATCH("allA_meancos_p1024_s42|s1kd-tools-doc_to_FOSSIG",'All Runs'!$A$2:$A$177,0)),"n/a") -> 1 | E33: =IFERROR(INDEX('All Runs'!$O$2:$O$177,MATCH("fixA_meancos_p1024_s42|s1kd-tools-doc_to_S1000D_spec_sample",'All Runs'!$A$2:$A$177,0)),"n/a") -> 0.95238095 | F33: =IFERROR(AVERAGE(B33:E33),"n/a") -> 0.8702381
A34: fossig | B34: =IFERROR(INDEX('All Runs'!$O$2:$O$177,MATCH("allA_meancos_p1024_s42|FOSSIG_to_BIKE_7",'All Runs'!$A$2:$A$177,0)),"n/a") -> 0.51944444 | C34: =IFERROR(INDEX('All Runs'!$O$2:$O$177,MATCH("allA_meancos_p1024_s42|FOSSIG_to_s1kd-tools-doc",'All Runs'!$A$2:$A$177,0)),"n/a") -> 0.83333333 | D34: — | E34: =IFERROR(INDEX('All Runs'!$O$2:$O$177,MATCH("fixA_meancos_p1024_s42|FOSSIG_to_S1000D_spec_sample",'All Runs'!$A$2:$A$177,0)),"n/a") -> 0.92857143 | F34: =IFERROR(AVERAGE(B34:E34),"n/a") -> 0.76044974
A35: s1000d-spec | B35: =IFERROR(INDEX('All Runs'!$O$2:$O$177,MATCH("allA_meancos_p1024_s42|S1000D_spec_sample_to_BIKE_7",'All Runs'!$A$2:$A$177,0)),"n/a") -> 0.91666667 | C35: =IFERROR(INDEX('All Runs'!$O$2:$O$177,MATCH("allA_meancos_p1024_s42|S1000D_spec_sample_to_s1kd-tools-doc",'All Runs'!$A$2:$A$177,0)),"n/a") -> 1 | D35: =IFERROR(INDEX('All Runs'!$O$2:$O$177,MATCH("allA_meancos_p1024_s42|S1000D_spec_sample_to_FOSSIG",'All Runs'!$A$2:$A$177,0)),"n/a") -> 1 | E35: — | F35: =IFERROR(AVERAGE(B35:E35),"n/a") -> 0.97222222
A36: Chance | B36: 0.4083 | C36: 0.6111 | D36: 0.75 | E36: 0.1736
A37: Test docs | B37: 6 | C37: 3 | D37: 2 | E37: 21
A39: CodeT5, config A, p2048 (allA_meancos_p2048_s42; no S1000D-target runs)
A40: Pretrain \ Finetune | B40: bike | C40: s1kd-tools-doc | D40: fossig | E40: s1000d-spec | F40: Row mean
A41: bike | B41: — | C41: =IFERROR(INDEX('All Runs'!$O$2:$O$177,MATCH("allA_meancos_p2048_s42|BIKE_7_to_s1kd-tools-doc",'All Runs'!$A$2:$A$177,0)),"n/a") -> 1 | D41: =IFERROR(INDEX('All Runs'!$O$2:$O$177,MATCH("allA_meancos_p2048_s42|BIKE_7_to_FOSSIG",'All Runs'!$A$2:$A$177,0)),"n/a") -> 0.75 | E41: =IFERROR(INDEX('All Runs'!$O$2:$O$177,MATCH("none|BIKE_7_to_S1000D_spec_sample",'All Runs'!$A$2:$A$177,0)),"n/a") -> n/a | F41: =IFERROR(AVERAGE(B41:E41),"n/a") -> 0.875
A42: s1kd-tools-doc | B42: =IFERROR(INDEX('All Runs'!$O$2:$O$177,MATCH("allA_meancos_p2048_s42|s1kd-tools-doc_to_BIKE_7",'All Runs'!$A$2:$A$177,0)),"n/a") -> 0.80555556 | C42: — | D42: =IFERROR(INDEX('All Runs'!$O$2:$O$177,MATCH("allA_meancos_p2048_s42|s1kd-tools-doc_to_FOSSIG",'All Runs'!$A$2:$A$177,0)),"n/a") -> 0.75 | E42: =IFERROR(INDEX('All Runs'!$O$2:$O$177,MATCH("none|s1kd-tools-doc_to_S1000D_spec_sample",'All Runs'!$A$2:$A$177,0)),"n/a") -> n/a | F42: =IFERROR(AVERAGE(B42:E42),"n/a") -> 0.77777778
A43: fossig | B43: =IFERROR(INDEX('All Runs'!$O$2:$O$177,MATCH("allA_meancos_p2048_s42|FOSSIG_to_BIKE_7",'All Runs'!$A$2:$A$177,0)),"n/a") -> 0.91666667 | C43: =IFERROR(INDEX('All Runs'!$O$2:$O$177,MATCH("allA_meancos_p2048_s42|FOSSIG_to_s1kd-tools-doc",'All Runs'!$A$2:$A$177,0)),"n/a") -> 1 | D43: — | E43: =IFERROR(INDEX('All Runs'!$O$2:$O$177,MATCH("none|FOSSIG_to_S1000D_spec_sample",'All Runs'!$A$2:$A$177,0)),"n/a") -> n/a | F43: =IFERROR(AVERAGE(B43:E43),"n/a") -> 0.95833333
A44: s1000d-spec | B44: =IFERROR(INDEX('All Runs'!$O$2:$O$177,MATCH("allA_meancos_p2048_s42|S1000D_spec_sample_to_BIKE_7",'All Runs'!$A$2:$A$177,0)),"n/a") -> 0.83333333 | C44: =IFERROR(INDEX('All Runs'!$O$2:$O$177,MATCH("allA_meancos_p2048_s42|S1000D_spec_sample_to_s1kd-tools-doc",'All Runs'!$A$2:$A$177,0)),"n/a") -> 1 | D44: =IFERROR(INDEX('All Runs'!$O$2:$O$177,MATCH("allA_meancos_p2048_s42|S1000D_spec_sample_to_FOSSIG",'All Runs'!$A$2:$A$177,0)),"n/a") -> 1 | E44: — | F44: =IFERROR(AVERAGE(B44:E44),"n/a") -> 0.94444444
A45: Chance | B45: 0.4083 | C45: 0.6111 | D45: 0.75 | E45: 0.1736
...

Sheet S1000D Target
A1: Finetune target S1000D_spec_sample (21 test docs), test MRR
A2: Chance 0.1736. Columns are the pretrain source; Mean / SD are across the three sources.
A4: Config | B4: Experiment tag | C4: Queries | D4: Seed | E4: BIKE_7 | F4: FOSSIG | G4: s1kd-tools-doc | H4: Mean | I4: SD | J4: Mean pretrain-dev MRR
A5: T5 baseline, first-token, dot, p256 | B5: t5_s42 | C5: original | D5: 42 | E5: =IFERROR(INDEX('All Runs'!$O$2:$O$177,MATCH("t5_s42|BIKE_7_to_S1000D_spec_sample",'All Runs'!$A$2:$A$177,0)),"n/a") -> 0.16706291 | F5: =IFERROR(INDEX('All Runs'!$O$2:$O$177,MATCH("t5_s42|FOSSIG_to_S1000D_spec_sample",'All Runs'!$A$2:$A$177,0)),"n/a") -> 0.20247593 | G5: =IFERROR(INDEX('All Runs'!$O$2:$O$177,MATCH("t5_s42|s1kd-tools-doc_to_S1000D_spec_sample",'All Runs'!$A$2:$A$177,0)),"n/a") -> 0.16657793 | H5: =AVERAGE(E5:G5) -> 0.17870559 | I5: =STDEV(E5:G5) -> 0.02058715 | J5: =IFERROR(AVERAGE(INDEX('All Runs'!$M$2:$M$177,MATCH("t5_s42|BIKE_7_to_S1000D_spec_sample",'All Runs'!$A$2:$A$177,0)),INDEX('All Runs'!$M$2:$M$177,MATCH("t5_s42|FOSSIG_to_S1000D_spec_sample",'All Runs'!$A$2:$A$177,0)),INDEX('All Runs'!$M$2:$M$177,MATCH("t5_s42|s1kd-tools-doc_to_S1000D_spec_sample",'All Runs'!$A$2:$A$177,0))),"n/a") -> 0.62731481
A6: CodeT5 baseline, first-token, dot, p256 | B6: codet5_s42 | C6: original | D6: 42 | E6: =IFERROR(INDEX('All Runs'!$O$2:$O$177,MATCH("codet5_s42|BIKE_7_to_S1000D_spec_sample",'All Runs'!$A$2:$A$177,0)),"n/a") -> 0.17765125 | F6: =IFERROR(INDEX('All Runs'!$O$2:$O$177,MATCH("codet5_s42|FOSSIG_to_S1000D_spec_sample",'All Runs'!$A$2:$A$177,0)),"n/a") -> 0.16310217 | G6: =IFERROR(INDEX('All Runs'!$O$2:$O$177,MATCH("codet5_s42|s1kd-tools-doc_to_S1000D_spec_sample",'All Runs'!$A$2:$A$177,0)),"n/a") -> 0.16955163 | H6: =AVERAGE(E6:G6) -> 0.17010168 | I6: =STDEV(E6:G6) -> 0.0072901176 | J6: =IFERROR(AVERAGE(INDEX('All Runs'!$M$2:$M$177,MATCH("codet5_s42|BIKE_7_to_S1000D_spec_sample",'All Runs'!$A$2:$A$177,0)),INDEX('All Runs'!$M$2:$M$177,MATCH("codet5_s42|FOSSIG_to_S1000D_spec_sample",'All Runs'!$A$2:$A$177,0)),INDEX('All Runs'!$M$2:$M$177,MATCH("codet5_s42|s1kd-tools-doc_to_S1000D_spec_sample",'All Runs'!$A$2:$A$177,0))),"n/a") -> 0.62731481
A7: CodeT5 baseline, first-token, dot, p256 (rerun) | B7: cnt_p256_s42 | C7: original | D7: 42 | E7: =IFERROR(INDEX('All Runs'!$O$2:$O$177,MATCH("cnt_p256_s42|BIKE_7_to_S1000D_spec_sample",'All Runs'!$A$2:$A$177,0)),"n/a") -> 0.17765125 | F7: =IFERROR(INDEX('All Runs'!$O$2:$O$177,MATCH("cnt_p256_s42|FOSSIG_to_S1000D_spec_sample",'All Runs'!$A$2:$A$177,0)),"n/a") -> 0.16310217 | G7: =IFERROR(INDEX('All Runs'!$O$2:$O$177,MATCH("cnt_p256_s42|s1kd-tools-doc_to_S1000D_spec_sample",'All Runs'!$A$2:$A$177,0)),"n/a") -> 0.16955163 | H7: =AVERAGE(E7:G7) -> 0.17010168 | I7: =STDEV(E7:G7) -> 0.0072901176 | J7: =IFERROR(AVERAGE(INDEX('All Runs'!$M$2:$M$177,MATCH("cnt_p256_s42|BIKE_7_to_S1000D_spec_sample",'All Runs'!$A$2:$A$177,0)),INDEX('All Runs'!$M$2:$M$177,MATCH("cnt_p256_s42|FOSSIG_to_S1000D_spec_sample",'All Runs'!$A$2:$A$177,0)),INDEX('All Runs'!$M$2:$M$177,MATCH("cnt_p256_s42|s1kd-tools-doc_to_S1000D_spec_sample",'All Runs'!$A$2:$A$177,0))),"n/a") -> 0.62731481
A8: CodeT5 baseline, first-token, dot, p1024 | B8: cnt_p1024_s42 | C8: original | D8: 42 | E8: =IFERROR(INDEX('All Runs'!$O$2:$O$177,MATCH("cnt_p1024_s42|BIKE_7_to_S1000D_spec_sample",'All Runs'!$A$2:$A$177,0)),"n/a") -> 0.15375841 | F8: =IFERROR(INDEX('All Runs'!$O$2:$O$177,MATCH("cnt_p1024_s42|FOSSIG_to_S1000D_spec_sample",'All Runs'!$A$2:$A$177,0)),"n/a") -> 0.19756524 | G8: =IFERROR(INDEX('All Runs'!$O$2:$O$177,MATCH("cnt_p1024_s42|s1kd-tools-doc_to_S1000D_spec_sample",'All Runs'!$A$2:$A$177,0)),"n/a") -> 0.17556277 | H8: =AVERAGE(E8:G8) -> 0.1756288 | I8: =STDEV(E8:G8) -> 0.021903491 | J8: =IFERROR(AVERAGE(INDEX('All Runs'!$M$2:$M$177,MATCH("cnt_p1024_s42|BIKE_7_to_S1000D_spec_sample",'All Runs'!$A$2:$A$177,0)),INDEX('All Runs'!$M$2:$M$177,MATCH("cnt_p1024_s42|FOSSIG_to_S1000D_spec_sample",'All Runs'!$A$2:$A$177,0)),INDEX('All Runs'!$M$2:$M$177,MATCH("cnt_p1024_s42|s1kd-tools-doc_to_S1000D_spec_sample",'All Runs'!$A$2:$A$177,0))),"n/a") -> 0.62731481
A9: Mean pooling, dot, p1024 (fixB) | B9: fixB_meandot_p1024_s42 | C9: original | D9: 42 | E9: =IFERROR(INDEX('All Runs'!$O$2:$O$177,MATCH("fixB_meandot_p1024_s42|BIKE_7_to_S1000D_spec_sample",'All Runs'!$A$2:$A$177,0)),"n/a") -> 0.85600907 | F9: =IFERROR(INDEX('All Runs'!$O$2:$O$177,MATCH("fixB_meandot_p1024_s42|FOSSIG_to_S1000D_spec_sample",'All Runs'!$A$2:$A$177,0)),"n/a") -> 0.84761905 | G9: =IFERROR(INDEX('All Runs'!$O$2:$O$177,MATCH("fixB_meandot_p1024_s42|s1kd-tools-doc_to_S1000D_spec_sample",'All Runs'!$A$2:$A$177,0)),"n/a") -> 0.92063492 | H9: =AVERAGE(E9:G9) -> 0.87475435 | I9: =STDEV(E9:G9) -> 0.03995458 | J9: =IFERROR(AVERAGE(INDEX('All Runs'!$M$2:$M$177,MATCH("fixB_meandot_p1024_s42|BIKE_7_to_S1000D_spec_sample",'All Runs'!$A$2:$A$177,0)),INDEX('All Runs'!$M$2:$M$177,MATCH("fixB_meandot_p1024_s42|FOSSIG_to_S1000D_spec_sample",'All Runs'!$A$2:$A$177,0)),INDEX('All Runs'!$M$2:$M$177,MATCH("fixB_meandot_p1024_s42|s1kd-tools-doc_to_S1000D_spec_sample",'All Runs'!$A$2:$A$177,0))),"n/a") -> 0.68981481
A10: Mean pooling, cosine, p256 (fixC) | B10: fixC_meancos_p256_s42 | C10: original | D10: 42 | E10: =IFERROR(INDEX('All Runs'!$O$2:$O$177,MATCH("fixC_meancos_p256_s42|BIKE_7_to_S1000D_spec_sample",'All Runs'!$A$2:$A$177,0)),"n/a") -> 0.53849206 | F10: =IFERROR(INDEX('All Runs'!$O$2:$O$177,MATCH("fixC_meancos_p256_s42|FOSSIG_to_S1000D_spec_sample",'All Runs'!$A$2:$A$177,0)),"n/a") -> 0.59232804 | G10: =IFERROR(INDEX('All Runs'!$O$2:$O$177,MATCH("fixC_meancos_p256_s42|s1kd-tools-doc_to_S1000D_spec_sample",'All Runs'!$A$2:$A$177,0)),"n/a") -> 0.54814815 | H10: =AVERAGE(E10:G10) -> 0.55965608 | I10: =STDEV(E10:G10) -> 0.028703704 | J10: =IFERROR(AVERAGE(INDEX('All Runs'!$M$2:$M$177,MATCH("fixC_meancos_p256_s42|BIKE_7_to_S1000D_spec_sample",'All Runs'!$A$2:$A$177,0)),INDEX('All Runs'!$M$2:$M$177,MATCH("fixC_meancos_p256_s42|FOSSIG_to_S1000D_spec_sample",'All Runs'!$A$2:$A$177,0)),INDEX('All Runs'!$M$2:$M$177,MATCH("fixC_meancos_p256_s42|s1kd-tools-doc_to_S1000D_spec_sample",'All Runs'!$A$2:$A$177,0))),"n/a") -> 0.77777778
A11: Config A: mean, cosine, p1024 (fixA) | B11: fixA_meancos_p1024_s42 | C11: original | D11: 42 | E11: =IFERROR(INDEX('All Runs'!$O$2:$O$177,MATCH("fixA_meancos_p1024_s42|BIKE_7_to_S1000D_spec_sample",'All Runs'!$A$2:$A$177,0)),"n/a") -> 0.8984127 | F11: =IFERROR(INDEX('All Runs'!$O$2:$O$177,MATCH("fixA_meancos_p1024_s42|FOSSIG_to_S1000D_spec_sample",'All Runs'!$A$2:$A$177,0)),"n/a") -> 0.92857143 | G11: =IFERROR(INDEX('All Runs'!$O$2:$O$177,MATCH("fixA_meancos_p1024_s42|s1kd-tools-doc_to_S1000D_spec_sample",'All Runs'!$A$2:$A$177,0)),"n/a") -> 0.95238095 | H11: =AVERAGE(E11:G11) -> 0.92645503 | I11: =STDEV(E11:G11) -> 0.027046302 | J11: =IFERROR(AVERAGE(INDEX('All Runs'!$M$2:$M$177,MATCH("fixA_meancos_p1024_s42|BIKE_7_to_S1000D_spec_sample",'All Runs'!$A$2:$A$177,0)),INDEX('All Runs'!$M$2:$M$177,MATCH("fixA_meancos_p1024_s42|FOSSIG_to_S1000D_spec_sample",'All Runs'!$A$2:$A$177,0)),INDEX('All Runs'!$M$2:$M$177,MATCH("fixA_meancos_p1024_s42|s1kd-tools-doc_to_S1000D_spec_sample",'All Runs'!$A$2:$A$177,0))),"n/a") -> 0.68981481
A12: Config A: mean, cosine, p1024 (fixA) | B12: fixA_meancos_p1024_s1 | C12: original | D12: 1 | E12: =IFERROR(INDEX('All Runs'!$O$2:$O$177,MATCH("fixA_meancos_p1024_s1|BIKE_7_to_S1000D_spec_sample",'All Runs'!$A$2:$A$177,0)),"n/a") -> 0.8531746 | F12: =IFERROR(INDEX('All Runs'!$O$2:$O$177,MATCH("fixA_meancos_p1024_s1|FOSSIG_to_S1000D_spec_sample",'All Runs'!$A$2:$A$177,0)),"n/a") -> 0.97619048 | G12: =IFERROR(INDEX('All Runs'!$O$2:$O$177,MATCH("fixA_meancos_p1024_s1|s1kd-tools-doc_to_S1000D_spec_sample",'All Runs'!$A$2:$A$177,0)),"n/a") -> 0.97619048 | H12: =AVERAGE(E12:G12) -> 0.93518519 | I12: =STDEV(E12:G12) -> 0.071023247 | J12: =IFERROR(AVERAGE(INDEX('All Runs'!$M$2:$M$177,MATCH("fixA_meancos_p1024_s1|BIKE_7_to_S1000D_spec_sample",'All Runs'!$A$2:$A$177,0)),INDEX('All Runs'!$M$2:$M$177,MATCH("fixA_meancos_p1024_s1|FOSSIG_to_S1000D_spec_sample",'All Runs'!$A$2:$A$177,0)),INDEX('All Runs'!$M$2:$M$177,MATCH("fixA_meancos_p1024_s1|s1kd-tools-doc_to_S1000D_spec_sample",'All Runs'!$A$2:$A$177,0))),"n/a") -> 0.8287037
A13: Config A: mean, cosine, p1024 (fixA) | B13: fixA_meancos_p1024_s2 | C13: original | D13: 2 | E13: =IFERROR(INDEX('All Runs'!$O$2:$O$177,MATCH("fixA_meancos_p1024_s2|BIKE_7_to_S1000D_spec_sample",'All Runs'!$A$2:$A$177,0)),"n/a") -> 0.79920635 | F13: =IFERROR(INDEX('All Runs'!$O$2:$O$177,MATCH("fixA_meancos_p1024_s2|FOSSIG_to_S1000D_spec_sample",'All Runs'!$A$2:$A$177,0)),"n/a") -> 0.95238095 | G13: =IFERROR(INDEX('All Runs'!$O$2:$O$177,MATCH("fixA_meancos_p1024_s2|s1kd-tools-doc_to_S1000D_spec_sample",'All Runs'!$A$2:$A$177,0)),"n/a") -> 0.91269841 | H13: =AVERAGE(E13:G13) -> 0.88809524 | I13: =STDEV(E13:G13) -> 0.079495924 | J13: =IFERROR(AVERAGE(INDEX('All Runs'!$M$2:$M$177,MATCH("fixA_meancos_p1024_s2|BIKE_7_to_S1000D_spec_sample",'All Runs'!$A$2:$A$177,0)),INDEX('All Runs'!$M$2:$M$177,MATCH("fixA_meancos_p1024_s2|FOSSIG_to_S1000D_spec_sample",'All Runs'!$A$2:$A$177,0)),INDEX('All Runs'!$M$2:$M$177,MATCH("fixA_meancos_p1024_s2|s1kd-tools-doc_to_S1000D_spec_sample",'All Runs'!$A$2:$A$177,0))),"n/a") -> 0.74537037
A14: Config A, MEP loss OFF in pretraining | B14: mepablate_s42 | C14: original | D14: 42 | E14: =IFERROR(INDEX('All Runs'!$O$2:$O$177,MATCH("mepablate_s42|BIKE_7_to_S1000D_spec_sample",'All Runs'!$A$2:$A$177,0)),"n/a") -> 0.83333333 | F14: =IFERROR(INDEX('All Runs'!$O$2:$O$177,MATCH("mepablate_s42|FOSSIG_to_S1000D_spec_sample",'All Runs'!$A$2:$A$177,0)),"n/a") -> 0.92857143 | G14: =IFERROR(INDEX('All Runs'!$O$2:$O$177,MATCH("mepablate_s42|s1kd-tools-doc_to_S1000D_spec_sample",'All Runs'!$A$2:$A$177,0)),"n/a") -> 0.8968254 | H14: =AVERAGE(E14:G14) -> 0.88624339 | I14: =STDEV(E14:G14) -> 0.048492864 | J14: =IFERROR(AVERAGE(INDEX('All Runs'!$M$2:$M$177,MATCH("mepablate_s42|BIKE_7_to_S1000D_spec_sample",'All Runs'!$A$2:$A$177,0)),INDEX('All Runs'!$M$2:$M$177,MATCH("mepablate_s42|FOSSIG_to_S1000D_spec_sample",'All Runs'!$A$2:$A$177,0)),INDEX('All Runs'!$M$2:$M$177,MATCH("mepablate_s42|s1kd-tools-doc_to_S1000D_spec_sample",'All Runs'!$A$2:$A$177,0))),"n/a") -> 0.68518519
A15: Config A, pretrain 100 epochs | B15: longpretrain100_s42 | C15: original | D15: 42 | E15: =IFERROR(INDEX('All Runs'!$O$2:$O$177,MATCH("longpretrain100_s42|BIKE_7_to_S1000D_spec_sample",'All Runs'!$A$2:$A$177,0)),"n/a") -> 0.87301587 | F15: =IFERROR(INDEX('All Runs'!$O$2:$O$177,MATCH("longpretrain100_s42|FOSSIG_to_S1000D_spec_sample",'All Runs'!$A$2:$A$177,0)),"n/a") -> 0.85714286 | G15: =IFERROR(INDEX('All Runs'!$O$2:$O$177,MATCH("longpretrain100_s42|s1kd-tools-doc_to_S1000D_spec_sample",'All Runs'!$A$2:$A$177,0)),"n/a") -> 0.94444444 | H15: =AVERAGE(E15:G15) -> 0.89153439 | I15: =STDEV(E15:G15) -> 0.046503693 | J15: =IFERROR(AVERAGE(INDEX('All Runs'!$M$2:$M$177,MATCH("longpretrain100_s42|BIKE_7_to_S1000D_spec_sample",'All Runs'!$A$2:$A$177,0)),INDEX('All Runs'!$M$2:$M$177,MATCH("longpretrain100_s42|FOSSIG_to_S1000D_spec_sample",'All Runs'!$A$2:$A$177,0)),INDEX('All Runs'!$M$2:$M$177,MATCH("longpretrain100_s42|s1kd-tools-doc_to_S1000D_spec_sample",'All Runs'!$A$2:$A$177,0))),"n/a") -> 0.68055556
A16: Config A, anonymized queries | B16: anonq_meancos_p1024_s42 | C16: anonymized | D16: 42 | E16: =IFERROR(INDEX('All Runs'!$O$2:$O$177,MATCH("anonq_meancos_p1024_s42|BIKE_7_to_S1000D_spec_sample",'All Runs'!$A$2:$A$177,0)),"n/a") -> 0.8968254 | F16: =IFERROR(INDEX('All Runs'!$O$2:$O$177,MATCH("anonq_meancos_p1024_s42|FOSSIG_to_S1000D_spec_sample",'All Runs'!$A$2:$A$177,0)),"n/a") -> 0.95238095 | G16: =IFERROR(INDEX('All Runs'!$O$2:$O$177,MATCH("anonq_meancos_p1024_s42|s1kd-tools-doc_to_S1000D_spec_sample",'All Runs'!$A$2:$A$177,0)),"n/a") -> 0.84126984 | H16: =AVERAGE(E16:G16) -> 0.8968254 | I16: =STDEV(E16:G16) -> 0.055555556 | J16: =IFERROR(AVERAGE(INDEX('All Runs'!$M$2:$M$177,MATCH("anonq_meancos_p1024_s42|BIKE_7_to_S1000D_spec_sample",'All Runs'!$A$2:$A$177,0)),INDEX('All Runs'!$M$2:$M$177,MATCH("anonq_meancos_p1024_s42|FOSSIG_to_S1000D_spec_sample",'All Runs'!$A$2:$A$177,0)),INDEX('All Runs'!$M$2:$M$177,MATCH("anonq_meancos_p1024_s42|s1kd-tools-doc_to_S1000D_spec_sample",'All Runs'!$A$2:$A$177,0))),"n/a") -> 0.72685185
A17: Config A, anonymized queries | B17: anonq_meancos_p1024_s1 | C17: anonymized | D17: 1 | E17: =IFERROR(INDEX('All Runs'!$O$2:$O$177,MATCH("anonq_meancos_p1024_s1|BIKE_7_to_S1000D_spec_sample",'All Runs'!$A$2:$A$177,0)),"n/a") -> 0.89285714 | F17: =IFERROR(INDEX('All Runs'!$O$2:$O$177,MATCH("anonq_meancos_p1024_s1|FOSSIG_to_S1000D_spec_sample",'All Runs'!$A$2:$A$177,0)),"n/a") -> 0.82539683 | G17: =IFERROR(INDEX('All Runs'!$O$2:$O$177,MATCH("anonq_meancos_p1024_s1|s1kd-tools-doc_to_S1000D_spec_sample",'All Runs'!$A$2:$A$177,0)),"n/a") -> 0.84920635 | H17: =AVERAGE(E17:G17) -> 0.85582011 | I17: =STDEV(E17:G17) -> 0.034213008 | J17: =IFERROR(AVERAGE(INDEX('All Runs'!$M$2:$M$177,MATCH("anonq_meancos_p1024_s1|BIKE_7_to_S1000D_spec_sample",'All Runs'!$A$2:$A$177,0)),INDEX('All Runs'!$M$2:$M$177,MATCH("anonq_meancos_p1024_s1|FOSSIG_to_S1000D_spec_sample",'All Runs'!$A$2:$A$177,0)),INDEX('All Runs'!$M$2:$M$177,MATCH("anonq_meancos_p1024_s1|s1kd-tools-doc_to_S1000D_spec_sample",'All Runs'!$A$2:$A$177,0))),"n/a") -> 0.74537037
A18: Config A, anonymized queries | B18: anonq_meancos_p1024_s2 | C18: anonymized | D18: 2 | E18: =IFERROR(INDEX('All Runs'!$O$2:$O$177,MATCH("anonq_meancos_p1024_s2|BIKE_7_to_S1000D_spec_sample",'All Runs'!$A$2:$A$177,0)),"n/a") -> 0.90238095 | F18: =IFERROR(INDEX('All Runs'!$O$2:$O$177,MATCH("anonq_meancos_p1024_s2|FOSSIG_to_S1000D_spec_sample",'All Runs'!$A$2:$A$177,0)),"n/a") -> 0.83333333 | G18: =IFERROR(INDEX('All Runs'!$O$2:$O$177,MATCH("anonq_meancos_p1024_s2|s1kd-tools-doc_to_S1000D_spec_sample",'All Runs'!$A$2:$A$177,0)),"n/a") -> 0.8015873 | H18: =AVERAGE(E18:G18) -> 0.8457672 | I18: =STDEV(E18:G18) -> 0.051534364 | J18: =IFERROR(AVERAGE(INDEX('All Runs'!$M$2:$M$177,MATCH("anonq_meancos_p1024_s2|BIKE_7_to_S1000D_spec_sample",'All Runs'!$A$2:$A$177,0)),INDEX('All Runs'!$M$2:$M$177,MATCH("anonq_meancos_p1024_s2|FOSSIG_to_S1000D_spec_sample",'All Runs'!$A$2:$A$177,0)),INDEX('All Runs'!$M$2:$M$177,MATCH("anonq_meancos_p1024_s2|s1kd-tools-doc_to_S1000D_spec_sample",'All Runs'!$A$2:$A$177,0))),"n/a") -> 0.60185185
A20: No-pretraining controls (base CodeT5 finetuned directly, config A, p1024)
A21: Config | B21: Experiment tag | C21: Queries | D21: Seed | E21: Test MRR | F21: Finetune dev MRR
A22: No pretraining | B22: nopre_meancos_p1024_s42 | C22: original | D22: 42 | E22: =IFERROR(INDEX('All Runs'!$O$2:$O$177,MATCH("nopre_meancos_p1024_s42|S1000D_spec_sample",'All Runs'!$A$2:$A$177,0)),"n/a") -> 0.91666667 | F22: =IFERROR(INDEX('All Runs'!$N$2:$N$177,MATCH("nopre_meancos_p1024_s42|S1000D_spec_sample",'All Runs'!$A$2:$A$177,0)),"n/a") -> 0.91071429
A23: No pretraining | B23: nopre_meancos_p1024_s1 | C23: original | D23: 1 | E23: =IFERROR(INDEX('All Runs'!$O$2:$O$177,MATCH("nopre_meancos_p1024_s1|S1000D_spec_sample",'All Runs'!$A$2:$A$177,0)),"n/a") -> 0.97619048 | F23: =IFERROR(INDEX('All Runs'!$N$2:$N$177,MATCH("nopre_meancos_p1024_s1|S1000D_spec_sample",'All Runs'!$A$2:$A$177,0)),"n/a") -> 0.94642857
A24: No pretraining | B24: nopre_meancos_p1024_s2 | C24: original | D24: 2 | E24: =IFERROR(INDEX('All Runs'!$O$2:$O$177,MATCH("nopre_meancos_p1024_s2|S1000D_spec_sample",'All Runs'!$A$2:$A$177,0)),"n/a") -> 0.97619048 | F24: =IFERROR(INDEX('All Runs'!$N$2:$N$177,MATCH("nopre_meancos_p1024_s2|S1000D_spec_sample",'All Runs'!$A$2:$A$177,0)),"n/a") -> 0.91071429
A25: No pretraining | B25: nopre_meancos_p1024_s3 | C25: original | D25: 3 | E25: =IFERROR(INDEX('All Runs'!$O$2:$O$177,MATCH("nopre_meancos_p1024_s3|S1000D_spec_sample",'All Runs'!$A$2:$A$177,0)),"n/a") -> 0.88095238 | F25: =IFERROR(INDEX('All Runs'!$N$2:$N$177,MATCH("nopre_meancos_p1024_s3|S1000D_spec_sample",'All Runs'!$A$2:$A$177,0)),"n/a") -> 0.87142857
A26: No pretraining | B26: nopre_meancos_p1024_s4 | C26: original | D26: 4 | E26: =IFERROR(INDEX('All Runs'!$O$2:$O$177,MATCH("nopre_meancos_p1024_s4|S1000D_spec_sample",'All Runs'!$A$2:$A$177,0)),"n/a") -> 0.95238095 | F26: =IFERROR(INDEX('All Runs'!$N$2:$N$177,MATCH("nopre_meancos_p1024_s4|S1000D_spec_sample",'All Runs'!$A$2:$A$177,0)),"n/a") -> 0.89880952
A27: No pretraining | B27: anonq_nopre_meancos_p1024_s42 | C27: anonymized | D27: 42 | E27: =IFERROR(INDEX('All Runs'!$O$2:$O$177,MATCH("anonq_nopre_meancos_p1024_s42|S1000D_spec_sample",'All Runs'!$A$2:$A$177,0)),"n/a") -> 0.9047619 | F27: =IFERROR(INDEX('All Runs'!$N$2:$N$177,MATCH("anonq_nopre_meancos_p1024_s42|S1000D_spec_sample",'All Runs'!$A$2:$A$177,0)),"n/a") -> 0.8452381
A28: No pretraining | B28: anonq_nopre_meancos_p1024_s1 | C28: anonymized | D28: 1 | E28: =IFERROR(INDEX('All Runs'!$O$2:$O$177,MATCH("anonq_nopre_meancos_p1024_s1|S1000D_spec_sample",'All Runs'!$A$2:$A$177,0)),"n/a") -> 0.82539683 | F28: =IFERROR(INDEX('All Runs'!$N$2:$N$177,MATCH("anonq_nopre_meancos_p1024_s1|S1000D_spec_sample",'All Runs'!$A$2:$A$177,0)),"n/a") -> 0.8452381
A29: No pretraining | B29: anonq_nopre_meancos_p1024_s2 | C29: anonymized | D29: 2 | E29: =IFERROR(INDEX('All Runs'!$O$2:$O$177,MATCH("anonq_nopre_meancos_p1024_s2|S1000D_spec_sample",'All Runs'!$A$2:$A$177,0)),"n/a") -> 0.80555556 | F29: =IFERROR(INDEX('All Runs'!$N$2:$N$177,MATCH("anonq_nopre_meancos_p1024_s2|S1000D_spec_sample",'All Runs'!$A$2:$A$177,0)),"n/a") -> 0.83928571
A31: Pretrained vs. no pretraining (config A)
A32: Query set | B32: Pretrained mean | C32: Pretrained SD | D32: n | E32: No-pretrain mean | F32: No-pretrain SD | G32: n | H32: Difference (pre - nopre)
A33: original | B33: =AVERAGE(E11:G11,E12:G12,E13:G13) -> 0.91657848 | C33: =STDEV(E11:G11,E12:G12,E13:G13) -> 0.059114258 | D33: =COUNT(E11:G11,E12:G12,E13:G13) -> 9 | E33: =AVERAGE(E22:E26) -> 0.94047619 | F33: =STDEV(E22:E26) -> 0.041239305 | G33: =COUNT(E22:E26) -> 5 | H33: =B33-E33 -> -0.023897707
A34: anonymized | B34: =AVERAGE(E16:G16,E17:G17,E18:G18) -> 0.86613757 | C34: =STDEV(E16:G16,E17:G17,E18:G18) -> 0.047716501 | D34: =COUNT(E16:G16,E17:G17,E18:G18) -> 9 | E34: =AVERAGE(E27:E29) -> 0.8452381 | F34: =STDEV(E27:E29) -> 0.052495066 | G34: =COUNT(E27:E29) -> 3 | H34: =B34-E34 -> 0.020899471
A35: Pretrained = 3 pretrain sources x 3 seeds. A difference smaller than ~1 SD means no pretraining benefit.
A37: Ablations vs. config A (seed 42)
A38: Comparison | B38: Config A mean | C38: Ablation mean | D38: Difference (ablation - A)
A39: MEP loss OFF | B39: =H11 -> 0.92645503 | C39: =H14 -> 0.88624339 | D39: =C39-B39 -> -0.04021164
A40: Pretrain 100 epochs | B40: =H11 -> 0.92645503 | C40: =H15 -> 0.89153439 | D40: =C40-B40 -> -0.034920635
A41: Mean + dot instead of cosine | B41: =H11 -> 0.92645503 | C41: =H9 -> 0.87475435 | D41: =C41-B41 -> -0.05170068
A42: p_max_len 256 instead of 1024 | B42: =H11 -> 0.92645503 | C42: =H10 -> 0.55965608 | D42: =C42-B42 -> -0.36679894
A43: Collapsed baseline (first-token, dot, p1024) | B43: =H11 -> 0.92645503 | C43: =H8 -> 0.1756288 | D43: =C43-B43 -> -0.75082622

Sheet Same Domain
A1: Same-domain pretraining: S1000D train split halved into A and B (config A, p1024)
A2: 'Harder' half = the one with the lower finetune-only (no-pretrain) baseline. Gain = pretrained - finetune-only on the same finetune half.
A4: Split | B4: Seed | C4: Experiment tag | D4: FT-only A | E4: FT-only B | F4: Pretrain B -> FT A | G4: Pretrain A -> FT B | H4: Gain on A | I4: Gain on B | J4: Harder half | K4: Gain on harder | L4: Gain on easier | M4: Pretrain-dev MRR (A) | N4: Pretrain-dev MRR (B)
A5: orig (150A/147B) | B5: 42 | C5: samedomain_s42 | D5: =IFERROR(INDEX('All Runs'!$O$2:$O$177,MATCH("samedomain_s42|finetuneA_only",'All Runs'!$A$2:$A$177,0)),"n/a") -> 0.80574452 | E5: =IFERROR(INDEX('All Runs'!$O$2:$O$177,MATCH("samedomain_s42|finetuneB_only",'All Runs'!$A$2:$A$177,0)),"n/a") -> 0.86309524 | F5: =IFERROR(INDEX('All Runs'!$O$2:$O$177,MATCH("samedomain_s42|pretrainB_finetuneA",'All Runs'!$A$2:$A$177,0)),"n/a") -> 0.93650794 | G5: =IFERROR(INDEX('All Runs'!$O$2:$O$177,MATCH("samedomain_s42|pretrainA_finetuneB",'All Runs'!$A$2:$A$177,0)),"n/a") -> 0.89880952 | H5: =F5-D5 -> 0.13076342 | I5: =G5-E5 -> 0.035714286 | J5: =IF(D5<E5,"A",IF(D5>E5,"B","tie")) -> A | K5: =IF(J5="B",I5,IF(J5="A",H5,"n/a")) -> 0.13076342 | L5: =IF(J5="B",H5,IF(J5="A",I5,"n/a")) -> 0.035714286 | M5: =IFERROR(INDEX('All Runs'!$M$2:$M$177,MATCH("samedomain_s42|pretrainA_finetuneB",'All Runs'!$A$2:$A$177,0)),"n/a") -> 0.39546049 | N5: =IFERROR(INDEX('All Runs'!$M$2:$M$177,MATCH("samedomain_s42|pretrainB_finetuneA",'All Runs'!$A$2:$A$177,0)),"n/a") -> 0.49166667
A6: orig (150A/147B) | B6: 1 | C6: samedomain_s1 | D6: =IFERROR(INDEX('All Runs'!$O$2:$O$177,MATCH("samedomain_s1|finetuneA_only",'All Runs'!$A$2:$A$177,0)),"n/a") -> 0.80045351 | E6: =IFERROR(INDEX('All Runs'!$O$2:$O$177,MATCH("samedomain_s1|finetuneB_only",'All Runs'!$A$2:$A$177,0)),"n/a") -> 0.8377551 | F6: =IFERROR(INDEX('All Runs'!$O$2:$O$177,MATCH("samedomain_s1|pretrainB_finetuneA",'All Runs'!$A$2:$A$177,0)),"n/a") -> 0.91156463 | G6: =IFERROR(INDEX('All Runs'!$O$2:$O$177,MATCH("samedomain_s1|pretrainA_finetuneB",'All Runs'!$A$2:$A$177,0)),"n/a") -> 0.8202381 | H6: =F6-D6 -> 0.11111111 | I6: =G6-E6 -> -0.017517007 | J6: =IF(D6<E6,"A",IF(D6>E6,"B","tie")) -> A | K6: =IF(J6="B",I6,IF(J6="A",H6,"n/a")) -> 0.11111111 | L6: =IF(J6="B",H6,IF(J6="A",I6,"n/a")) -> -0.017517007 | M6: =IFERROR(INDEX('All Runs'!$M$2:$M$177,MATCH("samedomain_s1|pretrainA_finetuneB",'All Runs'!$A$2:$A$177,0)),"n/a") -> 0.36285976 | N6: =IFERROR(INDEX('All Runs'!$M$2:$M$177,MATCH("samedomain_s1|pretrainB_finetuneA",'All Runs'!$A$2:$A$177,0)),"n/a") -> 0.50674603
A7: orig (150A/147B) | B7: 2 | C7: samedomain_s2 | D7: =IFERROR(INDEX('All Runs'!$O$2:$O$177,MATCH("samedomain_s2|finetuneA_only",'All Runs'!$A$2:$A$177,0)),"n/a") -> 0.79931973 | E7: =IFERROR(INDEX('All Runs'!$O$2:$O$177,MATCH("samedomain_s2|finetuneB_only",'All Runs'!$A$2:$A$177,0)),"n/a") -> 0.79931973 | F7: =IFERROR(INDEX('All Runs'!$O$2:$O$177,MATCH("samedomain_s2|pretrainB_finetuneA",'All Runs'!$A$2:$A$177,0)),"n/a") -> 0.85873016 | G7: =IFERROR(INDEX('All Runs'!$O$2:$O$177,MATCH("samedomain_s2|pretrainA_finetuneB",'All Runs'!$A$2:$A$177,0)),"n/a") -> 0.84070295 | H7: =F7-D7 -> 0.059410431 | I7: =G7-E7 -> 0.04138322 | J7: =IF(D7<E7,"A",IF(D7>E7,"B","tie")) -> tie | K7: =IF(J7="B",I7,IF(J7="A",H7,"n/a")) -> n/a | L7: =IF(J7="B",H7,IF(J7="A",I7,"n/a")) -> n/a | M7: =IFERROR(INDEX('All Runs'!$M$2:$M$177,MATCH("samedomain_s2|pretrainA_finetuneB",'All Runs'!$A$2:$A$177,0)),"n/a") -> 0.39478022 | N7: =IFERROR(INDEX('All Runs'!$M$2:$M$177,MATCH("samedomain_s2|pretrainB_finetuneA",'All Runs'!$A$2:$A$177,0)),"n/a") -> 0.45365646
A8: alt (143A/154B) | B8: 42 | C8: samedomain_alt_s42 | D8: =IFERROR(INDEX('All Runs'!$O$2:$O$177,MATCH("samedomain_alt_s42|finetuneA_only",'All Runs'!$A$2:$A$177,0)),"n/a") -> 0.78656463 | E8: =IFERROR(INDEX('All Runs'!$O$2:$O$177,MATCH("samedomain_alt_s42|finetuneB_only",'All Runs'!$A$2:$A$177,0)),"n/a") -> 0.84391534 | F8: =IFERROR(INDEX('All Runs'!$O$2:$O$177,MATCH("samedomain_alt_s42|pretrainB_finetuneA",'All Runs'!$A$2:$A$177,0)),"n/a") -> 0.85 | G8: =IFERROR(INDEX('All Runs'!$O$2:$O$177,MATCH("samedomain_alt_s42|pretrainA_finetuneB",'All Runs'!$A$2:$A$177,0)),"n/a") -> 0.85714286 | H8: =F8-D8 -> 0.063435374 | I8: =G8-E8 -> 0.013227513 | J8: =IF(D8<E8,"A",IF(D8>E8,"B","tie")) -> A | K8: =IF(J8="B",I8,IF(J8="A",H8,"n/a")) -> 0.063435374 | L8: =IF(J8="B",H8,IF(J8="A",I8,"n/a")) -> 0.013227513 | M8: =IFERROR(INDEX('All Runs'!$M$2:$M$177,MATCH("samedomain_alt_s42|pretrainA_finetuneB",'All Runs'!$A$2:$A$177,0)),"n/a") -> 0.46312616 | N8: =IFERROR(INDEX('All Runs'!$M$2:$M$177,MATCH("samedomain_alt_s42|pretrainB_finetuneA",'All Runs'!$A$2:$A$177,0)),"n/a") -> 0.68214286
C9: Mean (all 4) | D9: =AVERAGE(D5:D8) -> 0.7980206 | E9: =AVERAGE(E5:E8) -> 0.83602135 | F9: =AVERAGE(F5:F8) -> 0.88920068 | G9: =AVERAGE(G5:G8) -> 0.85422336 | H9: =AVERAGE(H5:H8) -> 0.091180083 | I9: =AVERAGE(I5:I8) -> 0.018202003 | K9: =AVERAGE(K5:K8) -> 0.10176997 | L9: =AVERAGE(L5:L8) -> 0.010474931 | M9: =AVERAGE(M5:M8) -> 0.40405666 | N9: =AVERAGE(N5:N8) -> 0.533553
C10: Min | D10: =MIN(D5:D8) -> 0.78656463 | E10: =MIN(E5:E8) -> 0.79931973 | F10: =MIN(F5:F8) -> 0.85 | G10: =MIN(G5:G8) -> 0.8202381 | H10: =MIN(H5:H8) -> 0.059410431 | I10: =MIN(I5:I8) -> -0.017517007 | K10: =MIN(K5:K8) -> 0.063435374 | L10: =MIN(L5:L8) -> -0.017517007 | M10: =MIN(M5:M8) -> 0.36285976 | N10: =MIN(N5:N8) -> 0.45365646
C11: Runs with gain > 0 | H11: =COUNTIF(H5:H8,">0")&" / "&COUNT(H5:H8) -> 4 / 4 | I11: =COUNTIF(I5:I8,">0")&" / "&COUNT(I5:I8) -> 3 / 4 | K11: =COUNTIF(K5:K8,">0")&" / "&COUNT(K5:K8) -> 3 / 3 | L11: =COUNTIF(L5:L8,">0")&" / "&COUNT(L5:L8) -> 2 / 3
A13: Pretrain-dev chance with 14 dev docs = 0.2323. Takeaway: pretraining helps the harder finetune half in every run; the easier half gains little.
